[2025-04-17 15:51:46 +0000] [5593] [INFO] Starting gunicorn 23.0.0
[2025-04-17 15:51:46 +0000] [5593] [INFO] Listening at: http://0.0.0.0:5000 (5593)
[2025-04-17 15:51:46 +0000] [5593] [INFO] Using worker: sync
[2025-04-17 15:51:46 +0000] [5599] [INFO] Booting worker with pid: 5599
[2025-04-17 15:51:46 +0000] [5599] [ERROR] Exception in worker process
Traceback (most recent call last):
  File "/home/runner/workspace/.pythonlibs/lib/python3.11/site-packages/gunicorn/arbiter.py", line 608, in spawn_worker
    worker.init_process()
  File "/home/runner/workspace/.pythonlibs/lib/python3.11/site-packages/gunicorn/workers/base.py", line 135, in init_process
    self.load_wsgi()
  File "/home/runner/workspace/.pythonlibs/lib/python3.11/site-packages/gunicorn/workers/base.py", line 147, in load_wsgi
    self.wsgi = self.app.wsgi()
                ^^^^^^^^^^^^^^^
  File "/home/runner/workspace/.pythonlibs/lib/python3.11/site-packages/gunicorn/app/base.py", line 66, in wsgi
    self.callable = self.load()
                    ^^^^^^^^^^^
  File "/home/runner/workspace/.pythonlibs/lib/python3.11/site-packages/gunicorn/app/wsgiapp.py", line 57, in load
    return self.load_wsgiapp()
           ^^^^^^^^^^^^^^^^^^^
  File "/home/runner/workspace/.pythonlibs/lib/python3.11/site-packages/gunicorn/app/wsgiapp.py", line 47, in load_wsgiapp
    return util.import_app(self.app_uri)
           ^^^^^^^^^^^^^^^^^^^^^^^^^^^^^
  File "/home/runner/workspace/.pythonlibs/lib/python3.11/site-packages/gunicorn/util.py", line 370, in import_app
    mod = importlib.import_module(module)
          ^^^^^^^^^^^^^^^^^^^^^^^^^^^^^^^
  File "/nix/store/clx0mcir7qw8zk36zbr4jra789g3knf6-python3-3.11.10/lib/python3.11/importlib/__init__.py", line 126, in import_module
    return _bootstrap._gcd_import(name[level:], package, level)
           ^^^^^^^^^^^^^^^^^^^^^^^^^^^^^^^^^^^^^^^^^^^^^^^^^^^^
  File "<frozen importlib._bootstrap>", line 1204, in _gcd_import
  File "<frozen importlib._bootstrap>", line 1176, in _find_and_load
  File "<frozen importlib._bootstrap>", line 1147, in _find_and_load_unlocked
  File "<frozen importlib._bootstrap>", line 690, in _load_unlocked
  File "<frozen importlib._bootstrap_external>", line 940, in exec_module
  File "<frozen importlib._bootstrap>", line 241, in _call_with_frames_removed
  File "/home/runner/workspace/minimal_app.py", line 54, in <module>
    import models
  File "/home/runner/workspace/models.py", line 2, in <module>
    from app import db
  File "/home/runner/workspace/app.py", line 58, in <module>
    from routes.auth import auth_bp
  File "/home/runner/workspace/routes/auth.py", line 5, in <module>
    from models import User, Role
ImportError: cannot import name 'User' from partially initialized module 'models' (most likely due to a circular import) (/home/runner/workspace/models.py)
[2025-04-17 15:51:46 +0000] [5599] [INFO] Worker exiting (pid: 5599)
[2025-04-17 15:51:46 +0000] [5593] [ERROR] Worker (pid:5599) exited with code 3
[2025-04-17 15:51:46 +0000] [5593] [ERROR] Shutting down: Master
[2025-04-17 15:51:46 +0000] [5593] [ERROR] Reason: Worker failed to boot.
